Workbook

Sheet ENERO
A2: DEPTO. | B2: EVALUADOR o EN FORMACIÓN | C2: CALIFICACIÓN | D2: # PARTICIPACIÓN | E2: J | F2: V | G2: S | H2: D | I2: L | J2: M | K2: M | L2: J | M2: V | N2: S | O2: D | P2: L | Q2: M | R2: M | S2: J | T2: V | U2: S | V2: D | W2: L | X2: M | Y2: M | Z2: J | AA2: V | AB2: S | AC2: D | AD2: L | AE2: M | AF2: M | AG2: J | AH2: V | AK2: EVALUACIÓN SEGÚN PLAN DE MANTENIMIENTO | AM2: Nro. | AN2: EVALUACIONES (AMPLIACIONES E INICIALES) | AO2: OBSERVACIONES | AP2: EJECUTADO | AS2: ORGANISMO DE INSPECCIÓN-ALCANCES
E3: 1 | F3: 2 | G3: 3 | H3: 4 | I3: 5 | J3: 6 | K3: 7 | L3: 8 | M3: 9 | N3: 10 | O3: 11 | P3: 12 | Q3: 13 | R3: 14 | S3: 15 | T3: 16 | U3: 17 | V3: 18 | W3: 19 | X3: 20 | Y3: 21 | Z3: 22 | AA3: 23 | AB3: 24 | AC3: 25 | AD3: 26 | AE3: 27 | AF3: 28 | AG3: 29 | AH3: 30 | AK3: RETRASADO | AS3: Evaluaciones | AT3: Testificaciones
A4: DIRECCIÓN DE INSPECCIÓN SAE | B4: EDISON AYALA | C4: EL | R4: CURSO DE ESTADÍSTICA DE EA Y/O CIL | AK4: EVALUADOR EN ENTRENAMIENTO | AS4: DE LA TORRE ASESORIA ALIMENTARIA AGDR CIA LTDA.
B5: ANDREA CELI | C5: EL | AE5: REVISIÓN | AK5: COMITÉ TECNICO/HOMOGEINIZACIONES/CURSOS | AS5: 1. Inspección de Plantas procesadores de alimentos buenas prácticas de manufactura
B6: AMPARITO VILLACIS | C6: EL | AE6: DE | AK6: OBSERVADOR
B7: JOHNY ROMERO | C7: E | W7: TEST. VARCO LP | X7: TEST. MAQUINARIAS Y SERVICIOS PETROLEROS MAQUISERPE CIA. LTDA. | AE7: EXPEDIENTES | AK7: VACACIONES
B8: KARLA BAUTISTA | C8: E | AK8: EVALUACIÓN PAR/AUDITORIA INTERNA | AS8: TRUSTOIL COMPANY S.A.
B9: EVELYN NARANJO | C9: E | AS9: 1. Inspección de pruebas de presión en tanques atmosféricos horizontales | AT9: 1. Inspección de ensayos no destructivos por ultrasonido medición de espesores
B10: STEVEN POZO | C10: OB | AS10: 2. Inspección de pruebas de presión en tuberías (hidrostáticas, neumáticas, hidroneumáticas) | AT10: 2. Inspección volumétrica Geométrica de Tanques Horizontales
B11: ALEJANDRO RIVADENEIRA | C11: OB | AM11: Nro. | AN11: EVALUACIONES MES | AO11: OBSERVACIONES | AP11: EJECUTADO | AT11: 3. Inspección de pruebas de presión en tanques atmosféricos horizontales
B12: DAVID ASIMBAYA | C12: DIR | P12: TECNIVALVULAS S.A. | AF12: TEST. VERIPET | AM12: 1 | AN12: DE LA TORRE ASESORIA ALIMENTARIA AGDR CIA LTDA. | AO12: Vigilancia 1 | AP12: ✔ | AT12: 4.Inspección de pruebas de presión en tuberías (hidrostáticas, neumáticas, hidroneumáticas)
A13: EVALUADORES EXTERNOS | B13: GUIDO REYES | C13: EL | D13: 2 | X13: VERIPET CIA LTDA. | AD13: TEST. VERIPET | AM13: 2 | AN13: INSPECTSERV S.A. | AO13: Vigilancia 2, se mueve para el mes de febrero | AP13: X
B14: GUNAR LLANOS | C14: EL | D14: 2 | Y14: VERIPET CIA LTDA. | AF14: TEST. VERIPET | AM14: 3 | AN14: CRANES ENGINEERING & OPERATOR ECUADOR CIA. LTDA. | AO14: Renovación | AP14: X | AS14: SICCPETR S.A.
B15: MENTOR PICO | C15: EL | D15: 1 | P15: TECNIVALVULAS S.A. | W15: TEST. TRUSTOIL COMPANY S.A. | AM15: 4 | AN15: TRUSTOIL COMPANY S.A. | AO15: Vigilancia 2 | AP15: ✔ | AS15: 1. Inspección de ensayos no destructivos por ultrasonido medición de espesores.
B16: VICTOR LARGO | C16: EL | D16: 1 | S16: TRUSTOIL COMPANY S.A. | AM16: 5 | AN16: SICCPETR S.A. | AO16: Vigilancia 2 | AP16: ✔ | AS16: 2. Ensayos no destructivos por ultrasonido convencional y arreglo de fases.
B17: KATIA LUZURIAGA | C17: EL | D17: 3 | X17: TEST. VERIPET CIA LTDA. | Y17: VERIPET CIA LTDA. | AD17: DE LA TORRE ASESORIA ALIMENTARIA AGDR CIA LTDA. | AM17: 6 | AN17: CONSORCIO SGS REVISIONES TÉCNICAS | AO17: Vigilancia 2, solicita cambiar para el mes de marzo | AP17: X
B18: MARIA MULKI | C18: EL | AM18: 7 | AN18: MINGA S.A. | AO18: Vigilancia 2, solicita cambiar para el mes de marzo | AP18: X | AT18: 1. Inspección de ensayos no destructivos por ultrasonido medición de espesores.
B19: PAMELA SIERRA | C19: E | S19: TRUSTOIL COMPANY S.A. | AM19: 8 | AT19: 2. Ensayos no destructivos por ultrasonido convencional y arreglo de fases.
B20: EMILIO PADILLA | C20: E | AT20: 3. Ensayos no destructivos por líquidos penetrantes.
B21: OSCAR CEVALLOS | C21: E | D21: 1 | M21: TEST. TECNIVALVULAS S.A. | P21: TECNIVALVULAS S.A. | AF21: TEST. SICCPETR S.A. | AG21: SICCPETR S.A.
B22: ANDRES MEDINA | C22: E | AM22: Nro. | AN22: PRIORIDAD | AO22: FECHA-PLAN DE MANTENIMIENTO | AP22: OBSERVACIONES | AQ22: EJECUTADO | AS22: VERIPET CIA LTDA.
B23: MARCOS ZAMBRANO | C23: E | AM23: 1 | AN23: AENORECUADOR S.A. | AO23: 45992 | AP23: Renovación, solicita se cambie para el mes de febrero | AQ23: ✔ | AS23: Inspección Volumétrica Líquida de Tanques Estacionarios | AT23: Inspección Volumétrica Líquida de Tanques Estacionarios
B24: ITAYA PESANTES | C24: E | AM24: 2 | AN24: VERIPET CIA LTDA. | AO24: 45992 | AP24: Vigilancia 2, EL OI solicta mover para enero 2025 | AQ24: ✔ | AS24: Inspección volumétrica Líquida de Carro Tanques (patio fijo) | AT24: Inspección volumétrica Líquida de Carro Tanques (patio fijo)
B25: DALILA CHILIQUINGA | C25: EL | D25: 1 | AG25: SICCPETR S.A. | AM25: 3 | AN25: TECNIVALVULAS S.A. | AO25: 45839 | AP25: Vigilancia 1 + Ampliación | AQ25: ✔ | AS25: Inspección volumétrica geométrica de Tanques horizontales | AT25: Inspección volumétrica geométrica de Tanques horizontales
B26: CESAR ESPINOSA | C26: EE | AS26: Inspección volumétrica geométrica Manual de tanques cilíndricos verticales por el Método Manual | AT26: Inspección volumétrica geométrica de esferas y esferoides
B27: DAMIAN ALEJANDRO | C27: EE | D27: 3 | S27: TRUSTOIL COMPANY S.A. | X27: TEST. VERIPET CIA LTDA. | Y27: VERIPET CIA LTDA. | AS27: Inspección volumétrica geométrica de esferas y esferoides | AT27: Inspección volumétrica geométrica de tanques cilíndricos verticales usando el método línea de referencia óptica
AS28: Inspección volumétrica geométrica de tanques cilíndricos verticales usando el método línea de referencia óptica | AT28: Inspección de medidores de desplazamiento positivo, turbinas por el método pipe prover
A29: EVALUADORES INTERNOS OTRAS ÁREAS SAE | B29: MIRIAM MAFLA | C29: EL | AS29: Inspección de medidores de desplazamiento positivo, turbinas por el método pipe prover | AT29: lnspección de medidores de Desplazamiento Positivo y Turbinas por el Método Tank Prover
B30: MANUEL SALAZAR | C30: E | AS30: lnspección de medidores de Desplazamiento Positivo y Turbinas por el Método Tank Prover | AT30: Inspección de Calidad y Cantidad de Hidrocarburos Líquidos en la Transferencia de Custodia
B31: CECILIA SIGCHA | C31: E | AS31: Inspección Volumétrica Geométrica y Óptica de Tanques Verticales | AT31: Inspección mediante pruebas para la detección de fuga en tanques atmosféricos verticales y horizontales (neumática, vacío, diésel.)
B32: CAROLINA PLAZA | C32: E | AS32: Inspección de Calidad y Cantidad de Hidrocarburos Líquidos en la Transferencia de Custodia | AT32: Inspección de cilindros de acero soldados para GLP
B33: GUICELA QUILIQUINGA | C33: OB | AS33: Inspección de equipos elevadores de personal | AT33: Inspección de válvulas para cilindros de GLP de uso doméstico
AS34: Inspección mediante pruebas para la detección de fuga en tanques atmosféricos verticales y horizontales (neumática, vacío, diésel.) | AT34: Inspección de reguladores de baja presión para GLP
AS35: Inspección de cilindros de acero soldados para GLP | AT35: Inspección de tanques para gases de baja presión nuevos
AS36: Inspección de válvulas para cilindros de GLP de uso doméstico | AT36: Inspección de talleres de reparación de cilindros de GLP
AS37: Inspección de reguladores de baja presión para GLP
AS38: Inspección de tanques para gases de baja presión nuevos
AS39: Inspección de talleres de reparación de cilindros de GLP
AS42: TECNIVALVULAS S.A.
AS43: 1) Inspección Visual Dimensional | AT43: Inspección de ensayos no destructivos por líquidos penetrantes
...

Sheet FEBRERO
A2: DEPTO. | B2: EVALUADOR o EN FORMACIÓN | C2: CALIFICACIÓN | D2: # PARTICIPACIÓN | E2: TOTAL PARTICIPACIÓN | F2: S | G2: D | H2: L | I2: M | J2: M | K2: J | L2: V | M2: S | N2: D | O2: L | P2: M | Q2: M | R2: J | S2: V | T2: S | U2: D | V2: L | W2: M | X2: M | Y2: J | Z2: V | AA2: S | AB2: D | AC2: L | AD2: M | AE2: M | AF2: J | AG2: V | AH2: S | AK2: EVALUACIÓN SEGÚN PLAN DE MANTENIMIENTO | AM2: Nro. | AN2: EVALUACIONES (AMPLIACIONES E INICIALES) | AO2: OBSERVACIONES | AP2: EJECUTADO | AS2: ORGANISMO DE INSPECCIÓN-ALCANCES
F3: 31 | G3: 1 | H3: 2 | I3: 3 | J3: 4 | K3: 5 | L3: 6 | M3: 7 | N3: 8 | O3: 9 | P3: 10 | Q3: 11 | R3: 12 | S3: 13 | T3: 14 | U3: 15 | V3: 16 | W3: 17 | X3: 18 | Y3: 19 | Z3: 20 | AA3: 21 | AB3: 22 | AC3: 23 | AD3: 24 | AE3: 25 | AF3: 26 | AG3: 27 | AH3: 28 | AK3: RETRASADO | AS3: Evaluaciones | AT3: Testificaciones
A4: DIRECCIÓN DE INSPECCIÓN SAE | B4: EDISON AYALA | C4: EL | E4: =D4+ENERO!D4 -> 0 | Q4: AUDITORIA INTERNA | AG4: COMITÉ DE HIDOCARBUROS | AK4: EVALUADOR EN ENTRENAMIENTO | AS4: INSPECTSERV S.A.
B5: ANDREA CELI | C5: EL | E5: =D5+ENERO!D5 -> 0 | AC5: AI | AD5: AI | AK5: COMITÉ TECNICO/HOMOGEINIZACIONES/CURSOS | AS5: 9. Inspección para la certificación en Buenas Prácticas de Almacenamiento, Distribución y/o Transporte
B6: AMPARITO VILLACIS | C6: EL | E6: =D6+ENERO!D6 -> 0 | AD6: AI | AK6: OBSERVADOR
B7: JOHNY ROMERO | C7: E | E7: =D7+ENERO!D7 -> 0 | H7: SERVICIOS MARITIMOS SERVINTMAR S.A.S. | J7: CURSO REQUISITOS LEGALES | X7: TEST. SERVICIOS MARITIMOS SERVINTMAR S.A.S. | AK7: VACACIONES
B8: KARLA BAUTISTA | C8: E | D8: 1 | E8: =D8+ENERO!D8 -> 1 | AF8: AENORECUADOR S.A. | AK8: EVALUACIÓN PAR/AUDITORIA INTERNA
B9: EVELYN NARANJO | C9: E | E9: =D9+ENERO!D9 -> 0
B10: STEVEN POZO | C10: OB | E10: =D10+ENERO!D10 -> 0
B11: ALEJANDRO RIVADENEIRA | C11: OB | E11: =D11+ENERO!D11 -> 0 | AM11: Nro. | AN11: EVALUACIONES MES | AO11: OBSERVACIONES | AP11: EJECUTADO | AS11: PROYECTOS, CONTRUCCIONES E INSTRUMENTACION PCI SAS
B12: DAVID ASIMBAYA | C12: DIR | E12: =D12+ENERO!D12 -> 0 | Y12: SEROIL INSTRUMENTS CIA. LTDA. | AM12: 1 | AN12: PROYECTOS, CONTRUCCIONES E INSTRUMENTACION PCI SAS | AO12: Vigilancia 1 | AP12: ✔ | AS12: 1) Inspección de medidores de desplazamiento positivo y turbinas por el método master meter
A13: EVALUADORES EXTERNOS | B13: GUIDO REYES | C13: EL | D13: 2 | E13: =D13+ENERO!D13 -> 4 | H13: SERVICIOS MARITIMOS SERVINTMAR S.A.S. | X13: TEST. SERVICIOS MARITIMOS SERVINTMAR S.A.S. | AD13: TEST. AENORECUADOR S.A. | AF13: AENORECUADOR S.A. | AM13: 2 | AN13: INSMAC S.A.S. | AO13: Vigilancia 2 | AP13: ✔
B14: GUNAR LLANOS | C14: EL | D14: 2 | E14: =D14+ENERO!D14 -> 4 | Y14: SEROIL INSTRUMENTS CIA. LTDA. | AM14: 3 | AN14: ESTANDARES NORMATIVAS & INSPECCION ENII S.A. | AO14: Vigilancia 1 | AP14: ✔
B15: MENTOR PICO | C15: EL | D15: 1 | E15: =D15+ENERO!D15 -> 2 | I15: TRUST CONTROL S.A. TCEE | O15: ESTANDARES NORMATIVAS & INSPECCION ENII S.A. | AM15: 4 | AN15: SEROIL INSTRUMENTS CIA. LTDA. | AO15: Vigilancia 2 | AP15: ✔
B16: VICTOR LARGO | C16: EL | D16: 1 | E16: =D16+ENERO!D16 -> 2 | Q16: INSMAC S.A.S. | AM16: 5 | AN16: AENORECUADOR S.A. | AO16: Renovación | AP16: ✔
B17: KATIA LUZURIAGA | C17: EL | E17: =D17+ENERO!D17 -> 3 | AD17: PROYECTOS, CONTRUCCIONES E INSTRUMENTACION PCI SAS | AM17: 6 | AN17: INSPECCIONES TÉCNICAS DEL AUSTRO INVEREH S.A. | AO17: Vigilancia 1 | AP17: X
B18: MARIA MULKI | C18: EL | D18: 1 | E18: =D18+ENERO!D18 -> 1 | I18: INSPECTSERV S.A. | AS18: INSMAC S.A.S.
B19: PAMELA SIERRA | C19: E | E19: =D19+ENERO!D19 -> 0 | AS19: 1) Inspección Visual Dimensional | AT19: 1) Inspección de ensayos no destructivos por partículas magnéticas
B20: EMILIO PADILLA | C20: E | D20: 2 | E20: =D20+ENERO!D20 -> 2 | K20: TEST. ESTANDARES NORMATIVAS & INSPECCION ENII S.A. | O20: ESTANDARES NORMATIVAS & INSPECCION ENII S.A. | AT20: 2) Inspección de ensayos no destructivos por líquidos penetrantes
B21: OSCAR CEVALLOS | C21: E | D21: 3 | E21: =D21+ENERO!D21 -> 4 | P21: TEST. INSMAC S.A.S. | Q21: INSMAC S.A.S. | R21: TEST. SEROIL INSTRUMENTS CIA. LTDA.
B22: ANDRES MEDINA | C22: E | E22: =D22+ENERO!D22 -> 0 | AM22: Nro. | AN22: PRIORIDAD | AO22: FECHA-PLAN DE MANTENIMIENTO | AP22: OBSERVACIONES | AQ22: EJECUTADO
B23: MARCOS ZAMBRANO | C23: E | E23: =D23+ENERO!D23 -> 0 | AM23: 1 | AN23: CONSORCIO SGS REVISIONES TÉCNICAS | AO23: 46023 | AP23: Vigilancia 2, solicita cambiar para el mes de marzo | AQ23: X
B24: ITAYA PESANTES | C24: E | E24: =D24+ENERO!D24 -> 0 | AM24: 2 | AN24: MINGA S.A. | AO24: 46023 | AP24: Vigilancia 2, solicita cambiar para el mes de marzo | AQ24: X
B25: DALILA CHILIQUINGA | C25: EL | E25: =D25+ENERO!D25 -> 1 | AM25: 3 | AN25: INSPECTSERV S.A. | AO25: 46023 | AP25: Vigilancia 2, se mueve para el mes de febrero | AQ25: ✔ | AS25: ESTANDARES NORMATIVAS & INSPECCION ENII S.A.
B26: CESAR ESPINOSA | C26: EE | E26: =D26+ENERO!D26 -> 0 | AM26: 4 | AN26: CRANES ENGINEERING & OPERATOR ECUADOR CIA. LTDA. | AO26: 46023 | AP26: Renovación, se pasa para el mes de marzo | AQ26: X | AS26: 1. Inspección de equipos elevadores de personal | AT26: 1. Inspección de tractores de pluma lateral
E27: =D27+ENERO!D27 -> 3 | AS27: 2. Inspección de winches | AT27: 2. Inspección de puentes grúa
E28: =D28+ENERO!D28 -> 0 | AS28: 3. Inspección de tractores de pluma lateral | AT28: 3. Inspección de seguridad de medios de transporte para hidrocarburos
A29: EVALUADORES INTERNOS OTRAS ÁREAS SAE | B29: MIRIAM MAFLA | C29: EL | E29: =D29+ENERO!D29 -> 0 | AS29: 4. Inspección de puentes grúa
B30: MANUEL SALAZAR | C30: E | E30: =D30+ENERO!D30 -> 0 | AD30: PROYECTOS, CONTRUCCIONES E INSTRUMENTACION PCI SAS | AS30: 5. Inspección de seguridad de medios de transporte para hidrocarburos
B31: CECILIA SIGCHA | C31: E | E31: =D31+ENERO!D31 -> 0
B32: CAROLINA PLAZA | C32: E | E32: =D32+ENERO!D32 -> 0
B33: GUICELA QUILIQUINGA | C33: OB | E33: =D33+ENERO!D33 -> 0
E34: =D34+ENERO!D34 -> 0
E35: =D35+ENERO!D35 -> 0
E36: =D36+ENERO!D36 -> 0 | AS36: SEROIL INSTRUMENTS CIA. LTDA.
AS37: 1. Inspección de pruebas de presión en tuberías (hidrostática) | AT37: 1. Inspección de pruebas de presión en tuberías (hidrostática)
AS40: AENORECUADOR S.A.
AS41: 1. Etiquetado de Calzado, Productos de marroquinería, Artículos de Viaje y Similares. (**) | AT41: 2. Inspección de Etiquetado de baldosas cerámicas para piso y pared
AS42: 2. Inspección de Etiquetado de baldosas cerámicas para piso y pared | AT42: 2. Inspección de Etiquetado de baldosas cerámicas para piso y pared (ampl)
AS49: SERVICIOS MARITIMOS SERVINTMAR S.A.S.
...

Sheet MARZO
A2: DEPTO. | B2: EVALUADOR o EN FORMACIÓN | C2: CALIFICACIÓN | D2: # PARTICIPACIÓN | E2: TOTAL PARTICIPACIÓN | F2: S | G2: D | H2: L | I2: M | J2: M | K2: J | L2: V | M2: S | N2: D | O2: L | P2: M | Q2: M | R2: J | S2: V | T2: S | U2: D | V2: L | W2: M | X2: M | Y2: J | Z2: V | AA2: S | AB2: D | AC2: L | AD2: M | AE2: M | AF2: J | AG2: V | AH2: S | AI2: D | AJ2: L | AK2: M | AN2: EVALUACIÓN SEGÚN PLAN DE MANTENIMIENTO | AP2: Nro. | AQ2: EVALUACIONES (AMPLIACIONES E INICIALES) | AR2: OBSERVACIONES | AS2: EJECUTADO | AV2: ORGANISMO DE INSPECCIÓN-ALCANCES
F3: 31 | G3: 1 | H3: 2 | I3: 3 | J3: 4 | K3: 5 | L3: 6 | M3: 7 | N3: 8 | O3: 9 | P3: 10 | Q3: 11 | R3: 12 | S3: 13 | T3: 14 | U3: 15 | V3: 16 | W3: 17 | X3: 18 | Y3: 19 | Z3: 20 | AA3: 21 | AB3: 22 | AC3: 23 | AD3: 24 | AE3: 25 | AF3: 26 | AG3: 27 | AH3: 28 | AI3: 29 | AJ3: 30 | AK3: 31 | AN3: RETRASADO | AP3: 1 | AQ3: JFW SERVICIOS DE INSPECCION Y. CERTIFICACION CIA. LTDA. | AR3: Ampliación + extraordinaria | AS3: ✔ | AV3: Evaluaciones | AW3: Testificaciones
A4: DIRECCIÓN DE INSPECCIÓN SAE | B4: EDISON AYALA | C4: EL | E4: =D4+FEBRERO!E4 -> 0 | P4: TEST. IPGMSERVICIOS AMBIENTALES CIA LTDA | Q4: JFW SERVICIOS DE INSPECCION Y. CERTIFICACION CIA. LTDA. | AC4: SERVICIOS DE INSPECCION Y GESTION DE CALIDAD RPMJ ASOCIADOS ITQM S A | AJ4: TEST. MINGA | AN4: EVALUADOR EN ENTRENAMIENTO | AP4: 2 | AQ4: VERIFBUCAY S.A. | AR4: Inicial | AS4: ✔ | AV4: JFW SERVICIOS DE INSPECCION Y. CERTIFICACION CIA. LTDA.
B5: ANDREA CELI | C5: EL | E5: =D5+FEBRERO!E5 -> 0 | O5: MINGA S.A. | AN5: COMITÉ TECNICO/HOMOGEINIZACIONES/CURSOS | AP5: 3 | AQ5: VERIFYCAR RTV MORONA SIMOVIL CIA .LTDA. | AR5: Inicial | AS5: ✔ | AV5: 1. Inspección de verticalidad, redondez y asentamiento de tanques de almacenamiento | AW5: 1. Inspección de pruebas hidrostáticas en tanques atmosféricos verticales
B6: AMPARITO VILLACIS | C6: EL | E6: =D6+FEBRERO!E6 -> 0 | AN6: OBSERVADOR | AV6: 2. Inspección de pruebas hidrostáticas en tanques atmosféricos verticales | AW6: 2. Inspección de pruebas de presión en recipientes a presión (hidrostáticas, neumáticas, hidroneumáticas)
B7: JOHNY ROMERO | C7: E | E7: =D7+FEBRERO!E7 -> 0 | AC7: SERVICIOS DE INSPECCION Y GESTION DE CALIDAD RPMJ ASOCIADOS ITQM S A | AE7: TEST. SERVICIOS DE INSPECCION Y GESTION DE CALIDAD RPMJ ASOCIADOS ITQM S A | AN7: VACACIONES | AV7: 3. Inspección de pruebas de presión en recipientes a presión (hidrostáticas, neumáticas, hidroneumáticas) | AW7: 3. Inspección de pruebas de presión en válvulas metálicas
B8: KARLA BAUTISTA | C8: E | E8: =D8+FEBRERO!E8 -> 1 | AN8: EVALUACIÓN PAR/AUDITORIA INTERNA | AV8: 4. Inspección de pruebas de presión en tuberías (hidrostáticas, neumáticas, hidroneumáticas) "alcance acreditado se incluye 1 procedimiento y 1 nueva norma." | AW8: 4. Inspección de verticalidad, redondez y asentamiento de tanques de almacenamiento
B9: EVELYN NARANJO | C9: E | E9: =D9+FEBRERO!E9 -> 0 | K9: TES. VERYGLOBE CIA. LTDA. | AV9: 5. Inspección de válvulas de seguridad y alivio de presión
B10: STEVEN POZO | C10: OB | E10: =D10+FEBRERO!E10 -> 0 | AV10: 6. Inspección de pruebas de presión en válvulas metálicas " Alcance acreditado se incluye 1 elemento y 3 nuevas normas"
B11: ALEJANDRO RIVADENEIRA | C11: OB | E11: =D11+FEBRERO!E11 -> 0 | AP11: Nro. | AQ11: EVALUACIONES MES | AR11: OBSERVACIONES | AS11: EJECUTADO | AV11: 7. Inspección de cables de acero
B12: DAVID ASIMBAYA | C12: DIR | E12: =D12+FEBRERO!E12 -> 0 | AP12: 1 | AQ12: CONTROL INTERNACIONAL DEL ECUADOR C.A. UNICONTROL | AR12: Vigilancia 2 | AS12: X | AV12: 8. Inspección de sistemas de elevación de personal (Canastas)
A13: EVALUADORES EXTERNOS | B13: GUIDO REYES | C13: EL | E13: =D13+FEBRERO!E13 -> 4 | V13: VERYGLOBE CIA. LTDA. | AC13: SERVICIOS DE INSPECCION Y GESTION DE CALIDAD RPMJ ASOCIADOS ITQM S A | AP13: 2 | AQ13: SERVICIOS DE INSPECCION Y GESTION DE CALIDAD RPMJ ASOCIADOS ITQM S A | AR13: Renovación | AS13: ✔
B14: GUNAR LLANOS | C14: EL | E14: =D14+FEBRERO!E14 -> 4 | O14: VERIFBUCAY S.A. | Q14: VERIFBUCAY S.A. | AC14: AMSPEC DE ECUADOR S.A. | AP14: 3 | AQ14: AMSPEC DE ECUADOR S.A. | AR14: Vigilancia 2 | AS14: ✔
B15: MENTOR PICO | C15: EL | E15: =D15+FEBRERO!E15 -> 2 | H15: CURSO METROLOGÍA | V15: VERIFYCAR RTV MORONA SIMOVIL CIA .LTDA. | X15: TEST. VERIFYCAR RTV MORONA SIMOVIL CIA .LTDA. | AP15: 4 | AQ15: VERYGLOBE CIA. LTDA. | AR15: Vigilancia 2 | AS15: ✔
B16: VICTOR LARGO | C16: EL | E16: =D16+FEBRERO!E16 -> 2 | O16: TEST. JFW SERVICIOS DE INSPECCION Y. CERTIFICACION CIA. LTDA. | Q16: JFW SERVICIOS DE INSPECCION Y. CERTIFICACION CIA. LTDA.
B17: KATIA LUZURIAGA | C17: EL | E17: =D17+FEBRERO!E17 -> 3 | O17: VERIFBUCAY S.A. | V17: VERYGLOBE CIA. LTDA. | AV17: CONTROL INTERNACIONAL DEL ECUADOR C.A. UNICONTROL
B18: MARIA MULKI | C18: EL | E18: =D18+FEBRERO!E18 -> 1 | O18: MINGA S.A. | AV18: 1)Inspección Volumétrica Geométrica de Tanques Horizontales
B19: PAMELA SIERRA | C19: E | E19: =D19+FEBRERO!E19 -> 0 | AV19: 2) Inspección de Medidores de Desplazamiento Positivo y Turbinas por el Método Tank Prover
B20: EMILIO PADILLA | C20: E | E20: =D20+FEBRERO!E20 -> 2 | Q20: JFW SERVICIOS DE INSPECCION Y. CERTIFICACION CIA. LTDA. | AV20: 3) Inspección Volumétrica Líquida de Tanques Estacionarios
B21: OSCAR CEVALLOS | C21: E | E21: =D21+FEBRERO!E21 -> 4 | AV21: 4) Inspección Volumétrica Líquida de Carro Tanques (Patio Fijo)
B22: ANDRES MEDINA | C22: E | E22: =D22+FEBRERO!E22 -> 0 | V22: VERYFICAR MORONA | AC22: CONTROL INTERNACIONAL DEL ECUADOR C.A. UNICONTROL | AP22: Nro. | AQ22: PRIORIDAD | AR22: FECHA-PLAN DE MANTENIMIENTO | AS22: OBSERVACIONES | AT22: EJECUTADO | AV22: 5) Inspección de Surtidores para derivados Líquidos de Petróleo
B23: MARCOS ZAMBRANO | C23: E | E23: =D23+FEBRERO!E23 -> 0 | AP23: 1 | AQ23: CONSORCIO SGS REVISIONES TÉCNICAS | AR23: 46023 | AS23: Vigilancia 2, solicita cambiar para el mes de marzo | AT23: X
B24: ITAYA PESANTES | C24: E | E24: =D24+FEBRERO!E24 -> 0 | AP24: 2 | AQ24: MINGA S.A. | AR24: 46023 | AS24: Vigilancia 2, solicita cambiar para el mes de marzo | AT24: ✔
B25: DALILA CHILIQUINGA | C25: EL | E25: =D25+FEBRERO!E25 -> 1 | AP25: 3 | AQ25: CRANES ENGINEERING & OPERATOR ECUADOR CIA. LTDA. | AR25: 46023 | AS25: Renovación, se pasa para el mes de marzo | AT25: X
B26: DAMIN ALEJANDRO | C26: EE | E26: =D26+FEBRERO!E26 -> 0 | AP26: 4 | AQ26: INSPECCIONES TÉCNICAS DEL AUSTRO INVEREH S.A. | AR26: 46054 | AS26: Vigilancia 1, OI suspendido (vence 2026-02-16) | AT26: X
B27: ELIZABETH FLORES | C27: EE | E27: =D27+FEBRERO!E27 -> 3 | K27: TEST. VERYGLOBE CIA. LTDA. | V27: VERYGLOBE CIA. LTDA.
E28: =D28+FEBRERO!E28 -> 0
A29: EVALUADORES INTERNOS OTRAS ÁREAS SAE | B29: MIRIAM MAFLA | C29: EL | E29: =D29+FEBRERO!E29 -> 0
B30: MANUEL SALAZAR | C30: E | E30: =D30+FEBRERO!E30 -> 0 | AV30: SERVICIOS DE INSPECCION Y GESTION DE CALIDAD RPMJ ASOCIADOS ITQM S A
B31: CECILIA SIGCHA | C31: E | E31: =D31+FEBRERO!E31 -> 0 | AV31: 1. Inspección mediante pruebas para la detección de fuga en tanques atmosféricos verticales y horizontales (neumática, vacío y diésel) | AW31: 1. Inspección de pruebas hidrostáticas en tanques Atmosféricos verticales
B32: CAROLINA PLAZA | C32: E | E32: =D32+FEBRERO!E32 -> 0 | AV32: 2. Inspección de pruebas hidrostáticas en tanques Atmosféricos verticales | AW32: 2. Inspección de pruebas de presión en tanques atmosféricos horizontales
B33: GUICELA QUILIQUINGA | C33: OB | E33: =D33+FEBRERO!E33 -> 0 | AV33: 3. Inspección de pruebas de presión en tanques atmosféricos horizontales | AW33: 3. Inspección de pruebas de presión en tuberías (hidrostáticas, neumáticas)
E34: =D34+FEBRERO!E34 -> 0 | AV34: 4. Inspección de pruebas de presión en recipientes a presión (hidrostáticas, neumáticas)
E35: =D35+FEBRERO!E35 -> 0 | AV35: 5. Inspección de pruebas de presión en tuberías (hidrostáticas, neumáticas)
E36: =D36+FEBRERO!E36 -> 0 | AV36: AMPLIACIÓN
AV37: 6. Inspección volumétrica geométrica de tanques cilíndricos verticales por el método de distancia electro óptica medición externa
AV38: 7. Inspección de horizontalidad, verticalidad, redondez, asentamiento
AV41: AMSPEC DE ECUADOR S.A.
AV42: 1. Inspección de Cantidad de Hidrocarburos Líquidos en Surtidores de Estaciones de Servicio
AV44: MINGA S.A.
...

Sheet ABRIL
A2: DEPTO. | B2: EVALUADOR o EN FORMACIÓN | C2: CALIFICACIÓN | D2: # PARTICIPACIÓN | E2: TOTAL PARTICIPACIÓN | F2: M | G2: J | H2: V | I2: S | J2: D | K2: L | L2: M | M2: M | N2: J | O2: V | P2: S | Q2: D | R2: L | S2: M | T2: M | U2: J | V2: V | W2: S | X2: D | Y2: L | Z2: M | AA2: M | AB2: J | AC2: V | AD2: S | AE2: D | AF2: L | AG2: M | AH2: M | AI2: J | AJ2: V | AK2: S | AL2: D | AO2: EVALUACIÓN SEGÚN PLAN DE MANTENIMIENTO | AQ2: Nro. | AR2: EVALUACIONES (AMPLIACIONES E INICIALES) | AS2: OBSERVACIONES | AT2: EJECUTADO | AW2: ORGANISMO DE INSPECCIÓN-ALCANCES
F3: 1 | G3: 2 | H3: 3 | I3: 4 | J3: 5 | K3: 6 | L3: 7 | M3: 8 | N3: 9 | O3: 10 | P3: 11 | Q3: 12 | R3: 13 | S3: 14 | T3: 15 | U3: 16 | V3: 17 | W3: 18 | X3: 19 | Y3: 20 | Z3: 21 | AA3: 22 | AB3: 23 | AC3: 24 | AD3: 25 | AE3: 26 | AF3: 27 | AG3: 28 | AH3: 29 | AI3: 30 | AJ3: 1 | AK3: 2 | AL3: 3 | AO3: RETRASADO | AW3: CONTROL INTERNACIONAL DEL ECUADOR C.A. UNICONTROL
A4: DIRECCIÓN DE INSPECCIÓN SAE | B4: EDISON AYALA | C4: EL | E4: =D4+MARZO!E4 -> 0 | T4: HOMOGENEIZACIÓN 2026 | Z4: TEST. PETROCHECK SERVICES CIA LTDA | AB4: SHATEC SERVICIOS DE INSPECCION NDT S.A. | AF4: CGA-OIL INSPECTION SERVICES S.A.S. | AO4: EVALUADOR EN ENTRENAMIENTO | AW4: 1)Inspección Volumétrica Geométrica de Tanques Horizontales | AX4: 1) Inspección Volumétrica Líquida de Tanques Estacionarios
B5: ANDREA CELI | C5: EL | E5: =D5+MARZO!E5 -> 0 | R5: FUALTEC ALTA TECNOLOGIA E INSPECCION S. A. | Z5: CURSO 17020 | AO5: COMITÉ TECNICO/HOMOGEINIZACIONES/CURSOS | AW5: 2) Inspección de Medidores de Desplazamiento Positivo y Turbinas por el Método Tank Prover | AX5: 2) Inspección Volumétrica Líquida de Carro Tanques (Patio Fijo)
B6: AMPARITO VILLACIS | C6: EL | E6: =D6+MARZO!E6 -> 0 | Z6: CURSO 17020 | AF6: MIDLANDEC S.A.S. | AO6: OBSERVADOR | AW6: 3) Inspección Volumétrica Líquida de Tanques Estacionarios | AX6: 3) Inspección de seguridad de medios de transporte para hidrocarburos
B7: JOHNY ROMERO | C7: E | E7: =D7+MARZO!E7 -> 0 | AO7: VACACIONES | AW7: 4) Inspección Volumétrica Líquida de Carro Tanques (Patio Fijo)
B8: KARLA BAUTISTA | C8: E | E8: =D8+MARZO!E8 -> 1 | AO8: EVALUACIÓN PAR/AUDITORIA INTERNA | AW8: 5) Inspección de Surtidores para derivados Líquidos de Petróleo
B9: EVELYN NARANJO | C9: E | E9: =D9+MARZO!E9 -> 0
B10: STEVEN POZO | C10: OB | E10: =D10+MARZO!E10 -> 0 | AF10: MIDLANDEC S.A.S. | AW10: MIDLANDEC S.A.S.
B11: ALEJANDRO RIVADENEIRA | C11: OB | E11: =D11+MARZO!E11 -> 0 | AB11: SHATEC SERVICIOS DE INSPECCION NDT S.A. | AQ11: Nro. | AR11: EVALUACIONES MES | AS11: OBSERVACIONES | AT11: EJECUTADO | AW11: 1) Inspección Visual Dimensional
B12: DAVID ASIMBAYA | C12: DIR | E12: =D12+MARZO!E12 -> 0 | R12: FUALTEC ALTA TECNOLOGIA E INSPECCION S. A. | AQ12: 1 | AR12: PETROCHECK SERVICES CIA LTDA | AS12: Vigilancia 2 | AT12: ✔ | AW12: 2) Inspección de ensayos no destructivos por partículas magnéticas
A13: EVALUADORES EXTERNOS | B13: GUIDO REYES | C13: EL | E13: =D13+MARZO!E13 -> 4 | AF13: PETROCHECK SERVICES CIA LTDA | AI13: TEST. PETROCHECK SERVICES CIA LTDA | AQ13: 2 | AR13: FUALTEC ALTA TECNOLOGIA E INSPECCION S. A. | AS13: Vigilancia 2 | AT13: ✔ | AW13: 3) Inspección de ensayos no destructivos por ultrasonido convencional
B14: GUNAR LLANOS | C14: EL | E14: =D14+MARZO!E14 -> 4 | AF14: TEST. REVIPLUS-ECUADOR S A | AG14: REVIPLUS-ECUADOR S A | AQ14: 3 | AR14: SHATEC SERVICIOS DE INSPECCION NDT S.A. | AS14: Vigilancia 2 | AT14: ✔
B15: MENTOR PICO | C15: EL | E15: =D15+MARZO!E15 -> 2 | Y15: CONTROL INTERNACIONAL DEL ECUADOR C.A. UNICONTROL | AA15: TEST. CONTROL INTERNACIONAL DEL ECUADOR C.A. UNICONTROL | AQ15: 4 | AR15: MIDLANDEC S.A.S. | AS15: Vigilancia 1 | AT15: ✔ | AW15: CGA-OIL INSPECTION SERVICES S.A.S.
B16: VICTOR LARGO | C16: EL | E16: =D16+MARZO!E16 -> 2 | M16: TEST. INSPECCIÓN SERVICIOS & COMERCIO, SSICOINTEC CÍA. LTDA. | N16: INSPECCIÓN SERVICIOS & COMERCIO, SSICOINTEC CÍA. LTDA. | AQ16: 5 | AR16: CGA-OIL INSPECTION SERVICES S.A.S. | AS16: Vigilancia 1 | AT16: ✔ | AW16: 1) Inspección de ensayos no destructivos por líquidos penetrantes | AX16: 1) Inspección de ensayos no destructivos por líquidos penetrantes
B17: KATIA LUZURIAGA | C17: EL | E17: =D17+MARZO!E17 -> 3 | AF17: PETROCHECK SERVICES CIA LTDA | AQ17: 6 | AR17: INSPECCIONES PROFESIONALES INSPECAGRO S.A. | AS17: Vigilancia 2, solicita para el mes de abril | AT17: X | AW17: 2) Inspección de ensayos no destructivos por ultrasonido medición de espesores | AX17: 2) Inspección de ensayos no destructivos por ultrasonido medición de espesores
B18: MARIA MULKI | C18: EL | E18: =D18+MARZO!E18 -> 1 | AQ18: 7 | AR18: FELVENZA S.A. | AS18: Renovación, solicita para el mes de abril | AT18: X
B19: PAMELA SIERRA | C19: E | E19: =D19+MARZO!E19 -> 0 | AF19: PETROCHECK SERVICES CIA LTDA | AQ19: 8 | AR19: REVIPLUS-ECUADOR S A | AS19: Renovación | AT19: ✔
B20: EMILIO PADILLA | C20: E | E20: =D20+MARZO!E20 -> 2 | Z20: TEST. SHATEC SERVICIOS DE INSPECCION NDT S.A. | AB20: SHATEC SERVICIOS DE INSPECCION NDT S.A. | AQ20: 9 | AR20: CEDINAP CENTRO DE INGENIERIA APLICADA PACE & SINCON CIA. LTDA | AS20: Vigilancia 2 | AT20: ✔ | AW20: PETROCHECK SERVICES CIA LTDA
B21: OSCAR CEVALLOS | C21: E | E21: =D21+MARZO!E21 -> 4 | R21: FUALTEC ALTA TECNOLOGIA E INSPECCION S. A. | AB21: SHATEC SERVICIOS DE INSPECCION NDT S.A. | AF21: CGA-OIL INSPECTION SERVICES S.A.S. | AG21: TEST. FUALTEC ALTA TECNOLOGIA E INSPECCION S. A. | AH21: TEST. CGA-OIL INSPECTION SERVICES S.A.S. | AW21: 1. Inspección Volumétrica Líquida de Carro Tanques (patio fijo) | AX21: 1. Inspección de seguridad de medios de transporte para hidrocarburos
B22: ANDRES MEDINA | C22: E | E22: =D22+MARZO!E22 -> 0 | AG22: REVIPLUS-ECUADOR S A | AQ22: Nro. | AR22: PRIORIDAD | AS22: FECHA-PLAN DE MANTENIMIENTO | AT22: OBSERVACIONES | AU22: EJECUTADO | AW22: 2. Inspección Volumétrica Geométrica de Tanques Horizontales | AX22: 2. Inspección volumétrica geométrica de tanques cilíndricos verticales por el método de distancia electro óptica interna. (Ampliación)
B23: MARCOS ZAMBRANO | C23: E | E23: =D23+MARZO!E23 -> 0 | Y23: CONTROL INTERNACIONAL DEL ECUADOR C.A. UNICONTROL | AQ23: 1 | AR23: CONSORCIO SGS REVISIONES TÉCNICAS | AS23: 46023 | AT23: Vigilancia 2, solicita cambiar para el mes de abril | AU23: X | AW23: 3. Inspección Volumétrica Líquida de Tanques Estacionarios
B24: DALILA CHILIQUINGA | C24: EL | E24: =D24+MARZO!E24 -> 0 | AQ24: 2 | AR24: CONTROL INTERNACIONAL DEL ECUADOR C.A. UNICONTROL | AS24: 46082 | AT24: Vigilancia 2, solicita cambiar para el mes de abril | AU24: ✔ | AW24: 4. Inspección Volumétrica Geométrica Manual de Tanques Cilíndricos Verticales por el Método Manual
B25: DAMIAN ALEJANDRO | C25: EE | E25: =D25+MARZO!E25 -> 1 | AQ25: 3 | AR25: CRANES ENGINEERING & OPERATOR ECUADOR CIA. LTDA. | AS25: 46023 | AT25: Renovación, se pasa para el mes de marzo | AU25: ✔ | AW25: 5. Inspección Volumétrica Geométrica de Tanques Cilíndricos Verticales por Método de Triangulación Óptica
B26: ELIZABETH FLORES | C26: EE | E26: =D26+MARZO!E26 -> 0 | AW26: 6. Inspección volumétrica geométrica de tanques cilíndricos verticales por el método de distancia electro óptica método externo
E27: =D27+MARZO!E27 -> 3 | AW27: 7. Inspección de vehículos que transportan materiales
E28: =D28+MARZO!E28 -> 0 | AW28: Ampliación
A29: EVALUADORES INTERNOS OTRAS ÁREAS SAE | B29: MIRIAM MAFLA | C29: EL | E29: =D29+MARZO!E29 -> 0 | AW29: 8. Inspección volumétrica líquida de carro tanques (Unidad móvil) | AX29: 3. Inspección Visual Dimensional
B30: MANUEL SALAZAR | C30: E | E30: =D30+MARZO!E30 -> 0 | AW30: 9. Inspección Visual Dimensional | AX30: 4. Inspección de válvulas para cilindros para GLP de uso doméstico
B31: CECILIA SIGCHA | C31: E | E31: =D31+MARZO!E31 -> 0 | AW31: 10. Inspección de cilindros de acero soldados para GLP | AX31: 5. Inspección de reguladores de baja presión para GLP
B32: CAROLINA PLAZA | C32: E | E32: =D32+MARZO!E32 -> 0 | AW32: 11. Inspección de reguladores de baja presión para GLP | AX32: 6. Inspección de cilindros de acero soldados para GLP
B33: GUICELA QUILIQUINGA | C33: OB | E33: =D33+MARZO!E33 -> 0 | AW33: 12. Inspección de válvulas para cilindros para GLP de uso doméstico
E34: =D34+MARZO!E34 -> 0 | AW34: 13. Inspección de cilindros de acero para gas licuado de petróleo en circulación
E35: =D35+MARZO!E35 -> 0 | AW35: 14. Inspección de seguridad de medios de transporte para hidrocarburos
E36: =D36+MARZO!E36 -> 0 | AW36: 15. Inspección de seguridad de centros de acopio de gas licuado de petróleo (GLP) en cilindros.
AW38: FUALTEC ALTA TECNOLOGIA E INSPECCION S. A.
AW39: 1. Inspección de ensayos no destructivos por partículas magnéticas | AX39: 1. Inspección de ensayos no destructivos por líquidos penetrantes
AX40: 2. Inspección de ensayos no destructivos por partículas magnéticas
AW41: SHATEC SERVICIOS DE INSPECCION NDT S.A.
AW42: 1. Inspección de ensayos no destructivos por líquidos penetrantes | AX42: Inspección de winches.
...

Sheet MAYO
A2: DEPTO. | B2: EVALUADOR o EN FORMACIÓN | C2: CALIFICACIÓN | D2: # PARTICIPACIÓN | E2: TOTAL PARTICIPACIÓN | F2: L | G2: M | H2: M | I2: J | J2: V | K2: S | L2: D | M2: L | N2: M | O2: M | P2: J | Q2: V | R2: S | S2: D | T2: L | U2: M | V2: M | W2: J | X2: V | Y2: S | Z2: D | AA2: L | AB2: M | AC2: M | AD2: J | AE2: V | AF2: S | AG2: D | AJ2: EVALUACIÓN SEGÚN PLAN DE MANTENIMIENTO | AL2: Nro. | AM2: EVALUACIONES (AMPLIACIONES E INICIALES) | AN2: OBSERVACIONES | AO2: EJECUTADO | AR2: ORGANISMO DE INSPECCIÓN-ALCANCES
F3: 4 | G3: 5 | H3: 6 | I3: 7 | J3: 8 | K3: 9 | L3: 10 | M3: 11 | N3: 12 | O3: 13 | P3: 14 | Q3: 15 | R3: 16 | S3: 17 | T3: 18 | U3: 19 | V3: 20 | W3: 21 | X3: 22 | Y3: 23 | Z3: 24 | AA3: 25 | AB3: 26 | AC3: 27 | AD3: 28 | AE3: 29 | AF3: 30 | AG3: 31 | AJ3: RETRASADO | AL3: 1 | AM3: SICALECUADOR | AN3: Ampliación documental | AO3: ✔ | AR3: ICONTEC INTERNATIONAL S.A
A4: DIRECCIÓN DE INSPECCIÓN SAE | B4: EDISON AYALA | C4: EL | E4: =D4+ABRIL!E4 -> 0 | AJ4: EVALUADOR EN ENTRENAMIENTO | AR4: 3,Inspección de Ensayos de Eficacia de Plaguicidas y Productos Afines de Uso Agrícola | AS4: 3,Inspección de Ensayos de Eficacia de Plaguicidas y Productos Afines de Uso Agrícola
B5: ANDREA CELI | C5: EL | E5: =D5+ABRIL!E5 -> 0 | AJ5: COMITÉ TECNICO/HOMOGEINIZACIONES/CURSOS
B6: AMPARITO VILLACIS | C6: EL | E6: =D6+ABRIL!E6 -> 0 | AJ6: OBSERVADOR | AR6: CENTRO DE INFORMACIÓN INTERNACIONAL EMPRESARIAL SOSTENIBLE CIIESOST S.A.
B7: JOHNY ROMERO | C7: E | E7: =D7+ABRIL!E7 -> 0 | AJ7: VACACIONES | AR7: 1) Niveles de emisión de gases contaminantes y nivel sonoro admisible en motocicletas
B8: KARLA BAUTISTA | C8: E | E8: =D8+ABRIL!E8 -> 1 | AJ8: EVALUACIÓN PAR/AUDITORIA INTERNA | AR8: 2) Dispositivos de seguridad esenciales
B9: EVELYN NARANJO | C9: E | E9: =D9+ABRIL!E9 -> 0
B10: STEVEN POZO | C10: OB | E10: =D10+ABRIL!E10 -> 0
B11: ALEJANDRO RIVADENEIRA | C11: OB | E11: =D11+ABRIL!E11 -> 0 | AL11: Nro. | AM11: EVALUACIONES MES | AN11: OBSERVACIONES | AO11: EJECUTADO
B12: DAVID ASIMBAYA | C12: DIR | E12: =D12+ABRIL!E12 -> 0 | AL12: 1 | AM12: ICONTEC INTERNATIONAL S.A | AN12: Vigilancia 2 | AO12: ✔ | AR12: CCCSOLUTIONS S.A.S.
A13: EVALUADORES EXTERNOS | B13: GUIDO REYES | C13: EL | E13: =D13+ABRIL!E13 -> 4 | J13: SERVICIOS DE INGENIERÍA DE CALIDAD SICALECUADOR S.A. | P13: CONSORCIO SGS REVISIONES TÉCNICAS | V13: SERVICIOS DE INSPECCIÓN Y GESTIÓN DE CALIDAD RPMJ ASOCIADOS ITQM S.A. | AL13: 2 | AM13: LABORATORIO METROSENS CIA. LTDA | AN13: Vigilancia 2, solicita para julio | AO13: X | AR13: 1) Inspección Visual Dimensional
B14: GUNAR LLANOS | C14: EL | E14: =D14+ABRIL!E14 -> 4 | AL14: 3 | AM14: ALLIANZ QUALITÁ CIA. LTDA | AN14: Renovación, solicita para julio | AO14: X | AR14: 2) Inspección de ensayos no destructivos por ultrasonido convencional y arreglo de fases
B15: MENTOR PICO | C15: EL | E15: =D15+ABRIL!E15 -> 2 | F15: CCCSOLUTIONS S.A.S. | H15: TEST. BUREAU VERITAS ECUADOR S.A. | T15: BUREAU VERITAS ECUADOR S.A. | AB15: GOBIERNO AUTONOMO DESCENTRALIZADO MUNICIPAL DEL CANTON PENIPE | AD15: GOBIERNO AUTONOMO DESCENTRALIZADO MUNICIPAL DEL CANTON PENIPE | AL15: 4 | AM15: INSPECTORES AGROINDUSTRIALES EC. | AN15: Renovación, solicita para julio | AO15: X
B16: VICTOR LARGO | C16: EL | E16: =D16+ABRIL!E16 -> 2 | AL16: 5 | AM16: CENTRO DE INFORMACIÓN INTERNACIONAL EMPRESARIAL SOSTENIBLE CIIESOST S.A. | AN16: Vigilancia 2 | AO16: ✔
B17: KATIA LUZURIAGA | C17: EL | E17: =D17+ABRIL!E17 -> 3 | AB17: GOBIERNO AUTONOMO DESCENTRALIZADO MUNICIPAL DEL CANTON PENIPE | AD17: CONSORCIO VERIFYCAR RTV ESMERALDAS | AL17: 6 | AM17: CONSORCIO VERIFYCAR RTV ESMERALDAS | AN17: Vigilancia 1 | AO17: ✔ | AR17: CONSORCIO VERIFYCAR RTV ESMERALDAS
B18: MARIA MULKI | C18: EL | E18: =D18+ABRIL!E18 -> 1 | M18: CENTRO DE INFORMACIÓN INTERNACIONAL EMPRESARIAL SOSTENIBLE CIIESOST S.A. | P18: CRANES ENGINEERING & OPERATOR ECUADOR CIA. LTDA. | AL18: 7 | AM18: SINDESECUADOR S.A | AN18: Vigilancia 1 | AO18: X | AR18: 1) Inspección técnica Vehicular
B19: PAMELA SIERRA | C19: E | E19: =D19+ABRIL!E19 -> 0 | AL19: 8 | AM19: SERVICIOS TECNICOS PETROLEROS & INDUSTRIALES SEVERTEEC CIA LTDA | AN19: Renovación, solicita para junio | AO19: X
B20: EMILIO PADILLA | C20: E | E20: =D20+ABRIL!E20 -> 2 | J20: TEST. CRANES ENGINEERING & OPERATOR ECUADOR CIA. LTDA. | AL20: 9 | AM20: CCCSOLUTIONS S.A.S. | AN20: Vigilancia 1 | AO20: ✔ | AR20: BUREAU VERITAS ECUADOR S.A.
B21: OSCAR CEVALLOS | C21: E | E21: =D21+ABRIL!E21 -> 4 | P21: CRANES ENGINEERING & OPERATOR ECUADOR CIA. LTDA. | T21: BUREAU VERITAS ECUADOR S.A. | V21: TEST, BUREAU VERITAS ECUADOR S.A. | AR21: 1. Inspección de seguridad de centros de distribución | AS21: 1. Inspección de seguridad de centros de distribución
B22: ANDRES MEDINA | C22: E | E22: =D22+ABRIL!E22 -> 0 | AL22: Nro. | AM22: PRIORIDAD | AN22: FECHA-PLAN DE MANTENIMIENTO | AO22: OBSERVACIONES | AP22: EJECUTADO | AR22: 2. Inspección de seguridad de medios de transporte para hidrocarburos | AS22: 2. Inspección técnica de tanques estacionarios verticales y horizontales de almacenamiento atmosféricos (enterrados y sobre superficie)
B23: MARCOS ZAMBRANO | C23: E | E23: =D23+ABRIL!E23 -> 0 | AL23: 1 | AM23: FELVENZA S.A. | AN23: 46113 | AO23: Renovación, solicita para el mes de junio | AP23: X | AR23: 3. Inspección técnica de tanques estacionarios verticales y horizontales de almacenamiento atmosféricos (enterrados y sobre superficie)
B24: DAMIAN ALEJANDRO | C24: EE | E24: =D24+ABRIL!E24 -> 0 | AL24: 2 | AM24: INSPECCIONES PROFESIONALES INSPECAGRO S.A. | AN24: 46113 | AO24: Vigilancia 2, solicita para el mes de junio | AP24: X | AR24: 4. Inspección de ensayos no destructivo por ultrasonido convencional y arreglo de fases
B25: DALILA CHILIQUINGA | C25: EL | E25: =D25+ABRIL!E25 -> 1 | AC25: TEST. ICONTEC INTERNATIONAL S.A | AD25: ICONTEC INTERNATIONAL S.A | AL25: 3 | AM25: CONSORCIO SGS REVISIONES TÉCNICAS | AN25: 46023 | AO25: Vigilancia 2, solicita cambiar para el mes | AP25: X
B26: CESAR ESPINOSA | C26: EE | E26: =D26+ABRIL!E26 -> 0
B27: ELIZABETH FLORES | C27: EE | E27: =D27+ABRIL!E27 -> 3 | M27: CENTRO DE INFORMACIÓN INTERNACIONAL EMPRESARIAL SOSTENIBLE CIIESOST S.A. | P27: CONSORCIO SGS REVISIONES TÉCNICAS | AD27: CONSORCIO VERIFYCAR RTV ESMERALDAS | AR27: CRANES ENGINEERING & OPERATOR ECUADOR CIA. LTDA.
E28: =D28+ABRIL!E28 -> 0 | AR28: 1) Inspección Visual Dimensional | AS28: 1) Inspección de Winches
A29: EVALUADORES INTERNOS OTRAS ÁREAS SAE | B29: MIRIAM MAFLA | C29: EL | E29: =D29+ABRIL!E29 -> 0 | AR29: 2) Inspección de ensayos no destructivos por líquidos penetrantes | AS29: 2) Inspección Visual Dimensional
B30: MANUEL SALAZAR | C30: E | E30: =D30+ABRIL!E30 -> 0
B31: CECILIA SIGCHA | C31: E | E31: =D31+ABRIL!E31 -> 0
B32: CAROLINA PLAZA | C32: E | E32: =D32+ABRIL!E32 -> 0 | AR32: SERVICIOS DE INSPECCIÓN Y GESTIÓN DE CALIDAD RPMJ ASOCIADOS ITQM S.A.
B33: GUICELA QUILIQUINGA | C33: OB | E33: =D33+ABRIL!E33 -> 0 | AR33: Inspección de pruebas hidrostáticas en tanques atmosféricos verticales” / Alcance correspondiente a la Renovación
E34: =D34+ABRIL!E34 -> 0
E35: =D35+ABRIL!E35 -> 0
E36: =D36+ABRIL!E36 -> 0 | AR36: CONSORCIO SGS REVISIONES TÉCNICAS
AR37: 1) Inspección técnica Vehicular
AQ40: SUSPENDIDO | AR40: Food Testing Solutions Ecuador S.A
AR41: Inspección pre embarque de productos pesqueros y acuícolas, | AS41: Inspección pre embarque de productos pesqueros y acuícolas,
AR44: SICALECUADOR
AR45: Inspección de cilindros de acero soldados para GLP

Sheet JUNIO
A2: DEPTO. | B2: EVALUADOR o EN FORMACIÓN | C2: CALIFICACIÓN | D2: # PARTICIPACIÓN | E2: TOTAL PARTICIPACIÓN | F2: L | G2: M | H2: M | I2: J | J2: V | K2: S | L2: D | M2: L | N2: M | O2: M | P2: J | Q2: V | R2: S | S2: D | T2: L | U2: M | V2: M | W2: J | X2: V | Y2: S | Z2: D | AA2: L | AB2: M | AC2: M | AD2: J | AE2: V | AF2: S | AG2: D | AH2: L | AI2: M | AJ2: M | AM2: EVALUACIÓN SEGÚN PLAN DE MANTENIMIENTO | AO2: Nro. | AP2: EVALUACIONES (AMPLIACIONES E INICIALES) | AQ2: OBSERVACIONES | AR2: EJECUTADO | AU2: ORGANISMO DE INSPECCIÓN-ALCANCES
F3: 1 | G3: 2 | H3: 3 | I3: 4 | J3: 5 | K3: 6 | L3: 7 | M3: 8 | N3: 9 | O3: 10 | P3: 11 | Q3: 12 | R3: 13 | S3: 14 | T3: 15 | U3: 16 | V3: 17 | W3: 18 | X3: 19 | Y3: 20 | Z3: 21 | AA3: 22 | AB3: 23 | AC3: 24 | AD3: 25 | AE3: 26 | AF3: 27 | AG3: 28 | AH3: 29 | AI3: 30 | AJ3: 1 | AM3: RETRASADO | AO3: 1 | AP3: SERVICIOS DE INSPECCIÓN E INGENIERÍA DEL ECUADOR SIISA S.A | AQ3: Inicial | AR3: ✔ | AU3: INSPECCIONES PROFESIONALES INSPECAGRO S.A.
A4: DIRECCIÓN DE INSPECCIÓN SAE | B4: EDISON AYALA | C4: EL | E4: =D4+MAYO!E4 -> 0 | AM4: EVALUADOR EN ENTRENAMIENTO | AO4: 2 | AP4: SERVICIOS INTEGRALES TÉCNICOS ELÉCTRICOS E INSTRUMENTACIÓN SITEINST S.A | AQ4: Inicial | AR4: ✔ | AU4: Inspección de ensayos de eficacia de Plaguicidas y productos afines de uso agrícola | AV4: Inspección de ensayos de eficacia de Plaguicidas y productos afines de uso agrícola
B5: ANDREA CELI | C5: EL | E5: =D5+MAYO!E5 -> 0 | AM5: COMITÉ TECNICO/HOMOGEINIZACIONES/CURSOS | AO5: 3 | AP5: EMPRESA PUBLICA DE LA MANCOMUNIDAD DE TRANSITO TRANSPORTE TERRESTRE Y SEGURIDAD VIAL DE LA PROVINCIA DE PASTAZA - TRANSC | AQ5: Inicial | AR5: ✔
B6: AMPARITO VILLACIS | C6: EL | E6: =D6+MAYO!E6 -> 0 | AM6: OBSERVADOR
B7: JOHNY ROMERO | C7: E | E7: =D7+MAYO!E7 -> 0 | AC7: CURSO REQUISITOS LEGALES | AM7: VACACIONES | AU7: FELVENZA S.A.
B8: KARLA BAUTISTA | C8: E | E8: =D8+MAYO!E8 -> 1 | U8: FELVENZA S.A. | AM8: EVALUACIÓN PAR/AUDITORIA INTERNA | AU8: Inspección de Alimentos Procesados (Leche) | AV8: Inspección de Alimentos Procesados (Cacao)
B9: EVELYN NARANJO | C9: E | E9: =D9+MAYO!E9 -> 0 | H9: SERVICIOS INTEGRALES TÉCNICOS ELÉCTRICOS E INSTRUMENTACIÓN SITEINST S.A.
B10: STEVEN POZO | C10: OB | E10: =D10+MAYO!E10 -> 0 | AU10: QUALITAS VERITAS PRODUCTOS Y SERVICIOS QUALIVERITAS CIA. LTDA.
B11: LORENA SANDOVAL | C11: OB | E11: =D11+MAYO!E11 -> 0 | AO11: Nro. | AP11: EVALUACIONES MES | AQ11: OBSERVACIONES | AR11: EJECUTADO | AU11: 1) Inspección de Ensayos no destructivos por Partículas magnéticas | AV11: 1) Inspección técnica de tanques estacionarios verticales y horizontales de almacenamiento atmosféricos (enterrados y sobre superficie)
B12: DAVID ASIMBAYA | C12: DIR | E12: =D12+MAYO!E12 -> 0 | AO12: 1 | AP12: IPGMSERVICIOS AMBIENTALES CIA. LTDA. | AQ12: Vigilancia 2, solicita para julio | AR12: X | AU12: 2) Inspección de ensayos no destructivos por Líquidos penetrantes | AV12: 2) Inspección de verticalidad, redondez y asentamiento de tanques de almacenamiento
A13: EVALUADORES EXTERNOS | B13: GUIDO REYES | C13: EL | E13: =D13+MAYO!E13 -> 4 | M13: CEDINAP CENTRO DE INGENIERIA APLICADA PACE & SINCON CIA. LTDA | AO13: 2 | AP13: ENGIPETROL S.A. | AQ13: Vigilancia 1 | AR13: ✔ | AU13: 3) Inspección de ensayos no destructivos por Ultrasonido, medición de espesores
B14: GUNAR LLANOS | C14: EL | E14: =D14+MAYO!E14 -> 4 | AA14: SERVICIOS DE INSPECCIÓN E INGENIERÍA DEL ECUADOR SIISA S.A | AH14: QUALITAS VERITAS PRODUCTOS Y SERVICIOS QUALIVERITAS CIA. LTDA. | AO14: 3 | AP14: VERIFTEST S.A. | AQ14: Vigilancia 2 | AR14: X | AU14: 4) Inspección de pruebas de presión en recipientes a presión (hidrostáticas, neumáticas, hidroneumáticas)
B15: MENTOR PICO | C15: EL | E15: =D15+MAYO!E15 -> 2 | F15: TEST. INSPECCIONES TÉCNICAS PETROLERAS TECNIPETRÓLEOS S.A | M15: INSPECCIONES TÉCNICAS PETROLERAS TECNIPETRÓLEOS S.A | AO15: 4 | AP15: CONSORCIO ALFRE CONSTRUCCIONES, CONSECIONES, CONSULTORIA Y SERVICIOS | AQ15: Vigilancia 1 | AR15: ✔ | AU15: 5) Inspección de pruebas de presión en tuberías (hidrostáticas, neumáticas, hidroneumáticas)
B16: VICTOR LARGO | C16: EL | E16: =D16+MAYO!E16 -> 2 | F16: TEST. SERVICIOS INTEGRALES TÉCNICOS ELÉCTRICOS E INSTRUMENTACIÓN SITEINST S.A. | H16: SERVICIOS INTEGRALES TÉCNICOS ELÉCTRICOS E INSTRUMENTACIÓN SITEINST S.A. | AO16: 5 | AU16: 6) Inspección técnica de tuberías de procesos en servicio
B17: KATIA LUZURIAGA | C17: EL | E17: =D17+MAYO!E17 -> 3 | N17: KAIROSIG S.A.S | U17: FELVENZA S.A. | W17: TEST. FELVENZA S.A. | AH17: QUALITAS VERITAS PRODUCTOS Y SERVICIOS QUALIVERITAS CIA. LTDA. | AJ17: QUALITAS VERITAS PRODUCTOS Y SERVICIOS QUALIVERITAS CIA. LTDA. | AU17: 7) Inspección técnica de recipientes a presión en servicio, fuera de servicio y/o reparados
B18: MARIA MULKI | C18: EL | E18: =D18+MAYO!E18 -> 1 | I18: INSPECCIONES PROFESIONALES INSPECAGRO S.A. | AA18: SERVICIOS DE INSPECCIÓN E INGENIERÍA DEL ECUADOR SIISA S.A | AU18: 8) Inspección técnica de tanques estacionarios verticales y horizontales de almacenamiento atmosféricos (enterrados y sobre superficie)
B19: PAMELA SIERRA | C19: E | E19: =D19+MAYO!E19 -> 0
B20: EMILIO PADILLA | C20: E | E20: =D20+MAYO!E20 -> 2
B21: OSCAR CEVALLOS | C21: E | E21: =D21+MAYO!E21 -> 4 | M21: INSPECCIONES TÉCNICAS PETROLERAS TECNIPETRÓLEOS S.A | AU21: INSPECCIONES TÉCNICAS PETROLERAS TECNIPETRÓLEOS S.A
B22: ANDRES MEDINA | C22: E | E22: =D22+MAYO!E22 -> 0 | AO22: Nro. | AP22: PRIORIDAD | AQ22: FECHA-PLAN DE MANTENIMIENTO | AR22: OBSERVACIONES | AS22: EJECUTADO | AU22: 1.Inspección de ensayos no destructivos por ultrasonido medición de espesores | AV22: 1. Inspección de Verticalidad, Asentamiento y Redondez para Tanques Verticales
B23: MARCOS ZAMBRANO | C23: E | E23: =D23+MAYO!E23 -> 0 | AO23: 1 | AP23: LABORATORIO METROSENS CIA. LTDA | AQ23: 46143 | AR23: Vigilancia 2, solicita para julio | AS23: X | AU23: 2. Inspección de pruebas de presión en tuberías (hidrostáticas, neumáticas) | AV23: 2. Inspección de seguridad en el transporte de gas natural Licuado (GNL)
B24: DAMIAN ALEJANDRO | C24: E | E24: =D24+MAYO!E24 -> 0 | M24: INSPECCIONES TÉCNICAS PETROLERAS TECNIPETRÓLEOS S.A | O24: TEST. INSPECCIONES TÉCNICAS PETROLERAS TECNIPETRÓLEOS S.A | AH24: TEST. QUALITAS VERITAS PRODUCTOS Y SERVICIOS QUALIVERITAS CIA. LTDA. | AI24: QUALITAS VERITAS PRODUCTOS Y SERVICIOS QUALIVERITAS CIA. LTDA. | AO24: 2 | AP24: ALLIANZ QUALITÁ CIA. LTDA | AQ24: 46143 | AR24: Renovación, solicita para julio | AS24: X | AU24: 3. Inspección de Verticalidad, Asentamiento y Redondez para Tanques Verticales
B25: DALILA CHILIQUINGA | C25: EL | E25: =D25+MAYO!E25 -> 1 | AO25: 3 | AP25: INSPECTORES AGROINDUSTRIALES EC. | AQ25: 46143 | AR25: Renovación, solicita para julio | AS25: X | AU25: 4. Inspección de pruebas de presión en recipientes a presión (hidrostáticas, neumáticas) | AV25: Ampliación:
B26: CESAR ESPINOSA | C26: EE | E26: =D26+MAYO!E26 -> 0 | AO26: 4 | AP26: SINDESECUADOR S.A | AQ26: 46143 | AR26: Vigilancia 1, solicita para julio | AS26: X | AU26: 5. Inspección de pruebas de presión en tanques atmosféricos horizontales
B27: ELIZABETH FLORES | C27: EE | E27: =D27+MAYO!E27 -> 3 | I27: INSPECCIONES PROFESIONALES INSPECAGRO S.A. | AO27: 5 | AP27: SERVICIOS TECNICOS PETROLEROS & INDUSTRIALES SEVERTEEC CIA LTDA | AQ27: 46143 | AR27: Renovación, solicita para julio | AS27: X | AU27: 6. Inspección mediante pruebas para la detección de fuga en tanques atmosféricos verticales y horizontales (Neumática, Vacío, diésel) | AV27: 3. Inspección de las condiciones de seguridad de las instalaciones de almacenamiento y regasificación de GNL
E28: =D28+MAYO!E28 -> 0 | AO28: 6 | AP28: FELVENZA S.A. | AQ28: 46113 | AR28: Renovación, solicita para el mes de junio | AS28: ✔ | AU28: 7. Inspección de Ensayos no Destructivos por Ultrasonido Arreglo de Fases | AV28: 4. Inspección de seguridad de centros de acopio de gas licuado de petróleo (GLP) en cilindros.
A29: EVALUADORES INTERNOS OTRAS ÁREAS SAE | B29: MIRIAM MAFLA | C29: EL | E29: =D29+MAYO!E29 -> 0 | AO29: 7 | AP29: INSPECCIONES PROFESIONALES INSPECAGRO S.A. | AQ29: 46113 | AR29: Vigilancia 2, solicita para el mes de junio | AS29: ✔ | AU29: 8. Inspección Visual Dimensional
B30: MANUEL SALAZAR | C30: E | E30: =D30+MAYO!E30 -> 0 | AO30: 8 | AP30: INSPECCIONES TÉCNICAS PETROLERAS TECNIPETRÓLEOS S.A | AQ30: 46266 | AR30: Vigilancia, Ampliación | AS30: ✔ | AU30: 9. Inspección técnica de tuberías de procesos en servicio
B31: CECILIA SIGCHA | C31: E | E31: =D31+MAYO!E31 -> 0 | AO31: 9 | AP31: QUALITAS VERITAS PRODUCTOS Y SERVICIOS QUALIVERITAS CIA. LTDA. | AQ31: 46266 | AR31: Renovación + Ampliación | AS31: ✔ | AU31: 10. Inspección de seguridad en el transporte de gas natural Licuado (GNL)
B32: CAROLINA PLAZA | C32: E | E32: =D32+MAYO!E32 -> 0
B33: GUICELA QUILIQUINGA | C33: OB | E33: =D33+MAYO!E33 -> 0 | AU33: Ampliación:
E34: =D34+MAYO!E34 -> 0 | AU34: 11. Inspección de las condiciones de seguridad de las instalaciones de almacenamiento y regasificación de GNL
E35: =D35+MAYO!E35 -> 0 | AU35: 12. Inspección de ensayos no destructivos con campo de fuga.
E36: =D36+MAYO!E36 -> 0 | AU36: 13. Inspección de seguridad de centros de acopio de gas licuado de petróleo (GLP) en cilindros.
AU39: CONSORCIO ALFRE CONSTRUCCIONES, CONSECIONES, CONSULTORIA Y SERVICIOS
AU40: Inspección técnica vehicular
AU43: ENGIPETROL S.A.
AU44: 1. Inspección de ensayos no destructivos por líquidos penetrantes
AU45: 2.Inspección de ensayos no destructivos por ultrasonido medición de espesores
...

Sheet JULIO
A2: DEPTO. | B2: EVALUADOR o EN FORMACIÓN | C2: CALIFICACIÓN | D2: # PARTICIPACIÓN | E2: TOTAL PARTICIPACIÓN | F2: M | G2: J | H2: V | I2: S | J2: D | K2: L | L2: M | M2: M | N2: J | O2: V | P2: S | Q2: D | R2: L | S2: M | T2: M | U2: J | V2: V | W2: S | X2: D | Y2: L | Z2: M | AA2: M | AB2: J | AC2: V | AD2: S | AE2: D | AF2: L | AG2: M | AH2: M | AI2: J | AJ2: V | AK2: S | AL2: D | AO2: EVALUACIÓN SEGÚN PLAN DE MANTENIMIENTO | AQ2: Nro. | AR2: EVALUACIONES (AMPLIACIONES E INICIALES) | AS2: OBSERVACIONES | AT2: EJECUTADO | AW2: ORGANISMO DE INSPECCIÓN-ALCANCES
F3: 1 | G3: 2 | H3: 3 | I3: 4 | J3: 5 | K3: 6 | L3: 7 | M3: 8 | N3: 9 | O3: 10 | P3: 11 | Q3: 12 | R3: 13 | S3: 14 | T3: 15 | U3: 16 | V3: 17 | W3: 18 | X3: 19 | Y3: 20 | Z3: 21 | AA3: 22 | AB3: 23 | AC3: 24 | AD3: 25 | AE3: 26 | AF3: 27 | AG3: 28 | AH3: 29 | AI3: 30 | AJ3: 31 | AK3: 1 | AL3: 2 | AO3: RETRASADO | AQ3: 1 | AR3: PACIFIC CONTROL ECU S.A.S | AS3: Ninguna | AT3: ✔
A4: DIRECCIÓN DE INSPECCIÓN SAE | B4: EDISON AYALA | C4: EL | E4: =D4+JUNIO!D4 -> 0 | AO4: EVALUADOR EN ENTRENAMIENTO | AW4: INTERTEK INTERNATIONAL LIMITED
B5: ANDREA CELI | C5: EL | E5: =D5+JUNIO!D5 -> 0 | F5: TEST. ALLIANZ QUALITÁ CIA. LTDA | G5: ALLIANZ QUALITÁ CIA. LTDA | AO5: COMITÉ TECNICO/HOMOGEINIZACIONES/CURSOS | AW5: Inspección para la certificación en buenas prácticas de almacenamiento, distribución y/o transporte
B6: AMPARITO VILLACIS | C6: EL | E6: =D6+JUNIO!D6 -> 0 | K6: POSIBLE TEST. SERVICIOS DE INSPECCIÓN E INGENIERÍA DEL ECUADOR SIISA S.A | AO6: OBSERVADOR
B7: JOHNY ROMERO | C7: E | E7: =D7+JUNIO!D7 -> 0 | AO7: VACACIONES | AW7: ALLIANZ QUALITÁ CIA. LTDA
B8: KARLA BAUTISTA | C8: E | E8: =D8+JUNIO!D8 -> 0 | G8: ALLIANZ QUALITÁ CIA. LTDA | AO8: EVALUACIÓN PAR/AUDITORIA INTERNA | AW8: 1. Inspección de plantas procesadores de alimentos Buenas Prácticas de Manufactura | AX8: 1. Inspección de plantas procesadores de alimentos Buenas Prácticas de Manufactura
B9: EVELYN NARANJO | C9: E | E9: =D9+JUNIO!D9 -> 0 | K9: POSIBLE TEST. SERVICIOS DE INSPECCIÓN E INGENIERÍA DEL ECUADOR SIISA S.A
B10: STEVEN POZO | C10: OB | E10: =D10+JUNIO!D10 -> 0
B11: LORENA SANDOVAL | C11: OB | E11: =D11+JUNIO!D11 -> 0 | AQ11: Nro. | AR11: EVALUACIONES MES | AS11: OBSERVACIONES | AT11: EJECUTADO
B12: DAVID ASIMBAYA | C12: DIR | E12: =D12+JUNIO!D12 -> 0 | AQ12: 1 | AR12: INTERTEK INTERNATIONAL LIMITED | AS12: Vigilancia 1 | AT12: ✔ | AW12: INSPECTORES AGROINDUSTRIALES EC.
A13: EVALUADORES EXTERNOS | B13: GUIDO REYES | C13: EL | E13: =D13+JUNIO!D13 -> 0 | AH13: EMPRESA PUBLICA MANCOMUNADA DE TRANSITO, TRANSPORTE TERRESTRE Y SEGURIDAD VIAL DE LOS GOBIERNOS AUTONOMOS DESCENTRALIZADOS MUNICIPALES DE LOS CANTONES DE BAÑOS DE AGUA SANTA, CEVALLOS, MOCHA, SANTIAGO DEQUERO, SAN PEDRO DE PELILEO, SANTIAGO DE PILLARO | AJ13: TEST. MPRESA PUBLICA MANCOMUNADA DE TRANSITO, TRANSPORTE TERRESTRE Y SEGURIDAD VIAL DE LOS GOBIERNOS AUTONOMOS DESCENTRALIZADOS MUNICIPALES DE LOS CANTONES DE BAÑOS DE AGUA SANTA, CEVALLOS, MOCHA, SANTIAGO DEQUERO, SAN PEDRO DE PELILEO, SANTIAGO DE PILLARO | AQ13: 2 | AR13: OSM-INSPECCIONES TECNICAS S.A.S. | AS13: Vigilancia 2, solicta se mueve para septiembre | AT13: X | AW13: 1. Inspección de plantas procesadores de alimentos Buenas Prácticas de Manufactura
B14: GUNAR LLANOS | C14: EL | E14: =D14+JUNIO!D14 -> 0 | G14: REVIPLUS-ECUADOR S A | R14: SERVICIOS TECNICOS PETROLEROS & INDUSTRIALES SEVERTEEC CIA LTDA | AQ14: 3 | AR14: SERVICIOS DE INSPECCIÓN E INTEGRIDAD DE ACTIVOS DEL ECUADOR SINACTEC S.A.S. | AS14: Renovación, solicta se mueve para septiembre | AT14: X
B15: MENTOR PICO | C15: EL | E15: =D15+JUNIO!D15 -> 0 | R15: SERVICIOS TECNICOS PETROLEROS & INDUSTRIALES SEVERTEEC CIA LTDA | AB15: TEST. SERVICIOS TECNICOS PETROLEROS & INDUSTRIALES SEVERTEEC CIA LTDA | AC15: TEST. SERVICIOS TECNICOS PETROLEROS & INDUSTRIALES SEVERTEEC CIA LTDA | AQ15: 4 | AR15: ECUA SUPERVISIONS S.A. ECUASUPERSA | AS15: Vigilancia 1, solicta se mueve para septiembre | AT15: X | AW15: SINDESECUADOR S.A
B16: VICTOR LARGO | C16: EL | E16: =D16+JUNIO!D16 -> 0 | AF16: SINDESECUADOR S.A | AH16: EMPRESA PUBLICA MANCOMUNADA DE TRANSITO, TRANSPORTE TERRESTRE Y SEGURIDAD VIAL DE LOS GOBIERNOS AUTONOMOS DESCENTRALIZADOS MUNICIPALES DE LOS CANTONES DE BAÑOS DE AGUA SANTA, CEVALLOS, MOCHA, SANTIAGO DEQUERO, SAN PEDRO DE PELILEO, SANTIAGO DE PILLARO | AQ16: 5 | AR16: BCIBUREAU CERTIFICACION & INSPECCIÓN DE EQUIPOS S.A. | AS16: Vigilancia 1, solicta se mueve para septiembre | AT16: X | AW16: 1. Inspección de ensayo no destructivo por líquidos penetrantes | AX16: 1. Inspección de ensayo no destructivo por líquidos penetrantes
B17: KATIA LUZURIAGA | C17: EL | E17: =D17+JUNIO!D17 -> 0 | K17: PACIFIC CONTROL ECUS SAS | Y17: INTERTEK INTERNATIONAL LIMITED | AQ17: 6 | AR17: S.G.S. DEL ECUADOR S.A. | AS17: Vigilancia 2, solicta se mueve para agosto | AT17: X | AW17: 2. Inspección de ensayos no destructivos por ultrasonido Medición de Espesores | AX17: 2. Inspección de ensayos no destructivos por ultrasonido Medición de Espesores
B18: MARIA MULKI | C18: EL | E18: =D18+JUNIO!D18 -> 0 | R18: INSPECTORES AGROINDUSTRIALES EC. | AW18: 3. Inspección de ensayos no destructivos por ultrasonido convencional y arreglo de fases | AX18: 3. Inspección de ensayos no destructivos por ultrasonido convencional y arreglo de fases
B19: PAMELA SIERRA | C19: E | E19: =D19+JUNIO!D19 -> 0 | R19: SERVICIOS TECNICOS PETROLEROS & INDUSTRIALES SEVERTEEC CIA LTDA | AW19: 4. Inspección de ensayos no destructivos por campo de fuga | AX19: 4. Inspección de ensayos no destructivos por campo de fuga
B20: EMILIO PADILLA | C20: E | E20: =D20+JUNIO!D20 -> 0
B21: OSCAR CEVALLOS | C21: E | E21: =D21+JUNIO!D21 -> 0 | AF21: SINDESECUADOR S.A | AH21: TEST. SINDESECUADOR S.A | AW21: SERVICIOS TECNICOS PETROLEROS & INDUSTRIALES SEVERTEEC CIA LTDA
B22: ANDRES MEDINA | C22: E | E22: =D22+JUNIO!D22 -> 0 | AW22: 1. Inspección volumétrica geométrica de tanques horizontales por el método manual | AX22: 1. Inspección volumétrica geométrica de tanques cilíndricos verticales por el método manual
B23: MARCOS ZAMBRANO | C23: E | E23: =D23+JUNIO!D23 -> 0 | K23: PACIFIC CONTROL ECUS SAS | AQ23: Nro. | AR23: PRIORIDAD | AS23: FECHA-PLAN DE MANTENIMIENTO | AT23: OBSERVACIONES | AU23: EJECUTADO | AW23: 2. Inspección volumétrica geométrica de tanques cilíndricos verticales por el método manual | AX23: 2. Inspección volumétrica geométrica de tanques cilíndricos verticales por el método de línea de referencia óptica
B24: DALILA CHILIQUINGA | C24: EL | E24: =D24+JUNIO!D24 -> 0 | AQ24: 1 | AR24: LABORATORIO METROSENS CIA. LTDA | AS24: 46143 | AT24: Vigilancia 2, solicita para julio | AU24: X | AW24: 3. Inspección volumétrica geométrica de tanques cilíndricos verticales por el método de línea de referencia óptica
B25: DAMIAN ALEJANDRO | C25: EE | E25: =D25+JUNIO!D25 -> 0 | AQ25: 2 | AR25: ALLIANZ QUALITÁ CIA. LTDA | AS25: 46143 | AT25: Renovación, solicita para julio | AU25: ✔ | AW25: 4. Inspección volumétrica líquida de auto tanques (unidad fija) | AX25: Extraordinaria:
B26: ELIZABETH FLORES | C26: EE | E26: =D26+JUNIO!D26 -> 0 | AQ26: 3 | AR26: INSPECTORES AGROINDUSTRIALES EC. | AS26: 46143 | AT26: Renovación, solicita para julio | AU26: ✔ | AW26: 5. Inspección de seguridad de medios de transporte para hidrocarburos | AX26: 1) Inspección de ensayos no destructivos por partículas magnéticas
E27: =D27+JUNIO!D27 -> 0 | AQ27: 4 | AR27: SINDESECUADOR S.A | AS27: 46143 | AT27: Vigilancia 1, solicita para julio | AU27: ✔ | AW27: 6. Inspección de seguridad de centros de distribución. | AX27: 2) Inspección de ensayos no destructivos por ultrasonido convencional y arreglo de fases
E28: =D28+JUNIO!D28 -> 0 | AQ28: 5 | AR28: SERVICIOS TECNICOS PETROLEROS & INDUSTRIALES SEVERTEEC CIA LTDA | AS28: 46143 | AT28: Renovación, solicita para julio | AU28: ✔ | AW28: 7. Inspección de verticalidad, redondez y asentamiento
A29: EVALUADORES INTERNOS OTRAS ÁREAS SAE | B29: MIRIAM MAFLA | C29: EL | E29: =D29+JUNIO!D29 -> 0 | AQ29: 1 | AR29: IPGMSERVICIOS AMBIENTALES CIA. LTDA. | AS29: 46174 | AT29: Vigilancia 2, solicita para septiembre | AU29: X | AW29: Extraordinaria:
B30: MANUEL SALAZAR | C30: E | E30: =D30+JUNIO!D30 -> 0 | AQ30: 2 | AR30: ENGIPETROL S.A. | AS30: 46174 | AT30: Vigilancia 1, se mueve para julio | AU30: ✔ | AW30: 1) Inspección de ensayos no destructivos por partículas magnéticas
B31: CECILIA SIGCHA | C31: E | E31: =D31+JUNIO!D31 -> 0 | R31: INSPECTORES AGROINDUSTRIALES EC. | AQ31: 3 | AR31: VERIFTEST S.A. | AS31: 46174 | AT31: Vigilancia 2, solicita para agosto | AU31: X | AW31: 2) Inspección de ensayos no destructivos por ultrasonido convencional y arreglo de fases
B32: CAROLINA PLAZA | C32: E | E32: =D32+JUNIO!D32 -> 0
B33: GUICELA QUILIQUINGA | C33: OB | E33: =D33+JUNIO!D33 -> 0 | AW33: REVIPLUS-ECUADOR S A
E34: =D34+JUNIO!D34 -> 0 | AW34: 1. Inspección técnica vehicular
E35: =D35+JUNIO!D35 -> 0
E36: =D36+JUNIO!D36 -> 0 | AW36: MPRESA PUBLICA MANCOMUNADA DE TRANSITO, TRANSPORTE TERRESTRE Y SEGURIDAD VIAL DE LOS GOBIERNOS AUTONOMOS DESCENTRALIZADOS MUNICIPALES DE LOS CANTONES DE BAÑOS DE AGUA SANTA, CEVALLOS, MOCHA, SANTIAGO DEQUERO, SAN PEDRO DE PELILEO, SANTIAGO DE PILLARO
AW37: 1. Inspección técnica vehicular | AX37: 1. Inspección técnica vehicular
AW40: PACIFIC CONTROL ECU S.A.S
AW41: Inspección de plantas procesadores de alimentos Buenas Prácticas de Manufactur | AX41: Inspección de plantas procesadores de alimentos Buenas Prácticas de Manufactur

Sheet AGOSTO
A2: DEPTO. | B2: EVALUADOR o EN FORMACIÓN | C2: CALIFICACIÓN | D2: # PARTICIPACIÓN | E2: TOTAL PARTICIPACIÓN | F2: L | G2: M | H2: M | I2: J | J2: V | K2: S | L2: D | M2: L | N2: M | O2: M | P2: J | Q2: V | R2: S | S2: D | T2: L | U2: M | V2: M | W2: J | X2: V | Y2: S | Z2: D | AA2: L | AB2: M | AC2: M | AD2: J | AE2: V | AF2: S | AG2: D | AJ2: EVALUACIÓN SEGÚN PLAN DE MANTENIMIENTO | AL2: Nro. | AM2: EVALUACIONES (AMPLIACIONES E INICIALES) | AN2: OBSERVACIONES | AO2: EJECUTADO | AR2: ORGANISMO DE INSPECCIÓN-ALCANCES
F3: 3 | G3: 4 | H3: 5 | I3: 6 | J3: 7 | K3: 8 | L3: 9 | M3: 10 | N3: 11 | O3: 12 | P3: 13 | Q3: 14 | R3: 15 | S3: 16 | T3: 17 | U3: 18 | V3: 19 | W3: 20 | X3: 21 | Y3: 22 | Z3: 23 | AA3: 24 | AB3: 25 | AC3: 26 | AD3: 27 | AE3: 28 | AF3: 29 | AG3: 30 | AJ3: RETRASADO | AR3: BUREAU VERITAS ECUADOR S.A.
A4: DIRECCIÓN DE INSPECCIÓN SAE | B4: EDISON AYALA | C4: EL | E4: =D4+JULIO!E4 -> 0 | I4: BUREAU VERITAS ECUADOR S.A. | V4: TEST. LENOR ECUADOR CIA. LTDA. | W4: LENOR ECUADOR CIA. LTDA. | AJ4: EVALUADOR EN ENTRENAMIENTO | AR4: 1) Inspección volumétrica geométrica de tanques cilíndricos verticales por método de triangulación óptica | AS4: 1) Inspección volumétrica geométrica de tanques cilíndricos verticales por método de triangulación óptica
B5: ANDREA CELI | C5: EL | E5: =D5+JULIO!E5 -> 0 | I5: WEBINAR | AJ5: COMITÉ TECNICO/HOMOGEINIZACIONES/CURSOS | AR5: 2) Inspección Volumétrica Geométrica de Tanques Cilíndricos Verticales por el Método de Distancia Externa Electro Óptica | AS5: 2) Inspección Volumétrica Geométrica de Tanques Cilíndricos Verticales por el Método de Distancia Externa Electro Óptica
B6: AMPARITO VILLACIS | C6: EL | E6: =D6+JULIO!E6 -> 0 | AJ6: OBSERVADOR | AR6: 3) Inspección Volumétrica Geométrica Carro Tanques y Vaccum | AS6: 3) Inspección Volumétrica Geométrica Interna Electro Óptica
B7: JOHNY ROMERO | C7: E | E7: =D7+JULIO!E7 -> 0 | AJ7: VACACIONES | AR7: 4) Inspección volumétrica geométrica Tanques horizontales | AS7: 4) Inspección de Calidad y Cantidad de Hidrocarburos Líquidos en la Transferencia de Custodia
